Workbook

Sheet البنية التحتية (AWS vs GCP)
A1: مقارنة تكاليف البنية التحتية السحابية الشهرية بالتفصيل (AWS vs GCP)
A2: سعر الصرف المعتمد: 1 دولار أمريكي = 0.709 دينار أردني (سعر مثبت). الأسعار محسوبة على أعلى تقدير بدوام كامل (On-Demand).
A4: المكون السحابي | B4: مواصفات AWS | C4: تكلفة AWS شهرياً ($ USD) | D4: تكلفة AWS شهرياً (JOD) | E4: مواصفات GCP | F4: تكلفة GCP شهرياً ($ USD) | G4: تكلفة GCP شهرياً (JOD)
A5: المستوى الأول: الشركات الناشئة (حتى 1,000 مستخدم نشط MAUs)
A6: واجهة المستخدم (Next.js) | B6: Fargate (0.25 vCPU, 0.5 GB RAM) | C6: 9.01 | D6: =C6*0.709 | E6: Cloud Run (0.25 vCPU, 0.5 GB RAM) | F6: 14.72 | G6: =F6*0.709
A7: الخلفية (Django Backend) | B7: Fargate (0.25 vCPU, 0.5 GB RAM) | C7: 9.01 | D7: =C7*0.709 | E7: Cloud Run (0.25 vCPU, 0.5 GB RAM) | F7: 14.72 | G7: =F7*0.709
A8: المهام الخلفية (Celery Worker) | B8: Fargate (0.25 vCPU, 0.5 GB RAM) | C8: 9.01 | D8: =C8*0.709 | E8: Cloud Run (0.25 vCPU, 0.5 GB RAM) | F8: 14.72 | G8: =F8*0.709
A9: مجدول المهام (Celery Beat) | B9: Fargate (0.25 vCPU, 0.5 GB RAM) | C9: 9.01 | D9: =C9*0.709 | E9: Cloud Run (0.25 vCPU, 0.5 GB RAM) | F9: 14.72 | G9: =F9*0.709
A10: ذاكرة التخزين المؤقت (Redis) | B10: Fargate Redis Task (0.25 vCPU, 0.5 GB RAM) | C10: 9.01 | D10: =C10*0.709 | E10: Cloud Run Redis Instance | F10: 14.72 | G10: =F10*0.709
A11: قاعدة البيانات (PostgreSQL) | B11: RDS db.t4g.micro (Single-AZ, 20GB SSD) | C11: 13.98 | D11: =C11*0.709 | E11: Cloud SQL db-g1-small (1.7GB RAM, 20GB SSD) | F11: 28.95 | G11: =F11*0.709
A12: موزع الأحمال (Load Balancer) | B12: 1 ALB (Application Load Balancer) | C12: 22.27 | D12: =C12*0.709 | E12: Cloud Load Balancing | F12: 20.25 | G12: =F12*0.709
A13: تخزين الملفات (S3 / Storage) | B13: Amazon S3 (50 GB storage & transfer) | C13: 3.15 | D13: =C13*0.709 | E13: Cloud Storage (50 GB storage & transfer) | F13: 3 | G13: =F13*0.709
A14: شبكة توصيل المحتوى (CDN) | B14: CloudFront (100 GB transfer) | C14: 3 | D14: =C14*0.709 | E14: Cloud CDN (100 GB transfer) | F14: 3 | G14: =F14*0.709
A15: تكاليف متنوعة (DNS/Monitoring) | B15: Route 53, CloudWatch, ACM | C15: 5 | D15: =C15*0.709 | E15: Cloud DNS, Monitoring & Logging | F15: 5 | G15: =F15*0.709
A16: إجمالي تكاليف البنية التحتية | C16: =SUM(C6:C15) | D16: =SUM(D6:D15) | F16: =SUM(F6:F15) | G16: =SUM(G6:G15)
A19: المستوى الثاني: مرحلة النمو (حتى 10,000 مستخدم نشط MAUs)
A20: واجهة المستخدم (Next.js) | B20: 2 Fargate Tasks (0.5 vCPU, 1 GB RAM) - HA | C20: 36.04 | D20: =C20*0.709 | E20: 2 Cloud Run Instances (0.5 vCPU, 1 GB RAM) | F20: 58.87 | G20: =F20*0.709
A21: الخلفية (Django Backend) | B21: 2 Fargate Tasks (1 vCPU, 2 GB RAM) - HA | C21: 72.08 | D21: =C21*0.709 | E21: 2 Cloud Run Instances (1 vCPU, 2 GB RAM) | F21: 117.73 | G21: =F21*0.709
A22: المهام الخلفية (Celery Worker) | B22: 2 Fargate Tasks (0.5 vCPU, 1 GB RAM) | C22: 36.04 | D22: =C22*0.709 | E22: 2 Cloud Run Instances (0.5 vCPU, 1 GB RAM) | F22: 58.87 | G22: =F22*0.709
A23: مجدول المهام (Celery Beat) | B23: 1 Fargate Task (0.25 vCPU, 0.5 GB RAM) | C23: 9.01 | D23: =C23*0.709 | E23: 1 Cloud Run Instance (0.25 vCPU, 0.5 GB RAM) | F23: 14.72 | G23: =F23*0.709
A24: قاعدة البيانات (PostgreSQL) | B24: RDS db.t4g.medium (Multi-AZ, 50GB SSD) | C24: 110.78 | D24: =C24*0.709 | E24: Cloud SQL Custom (2 vCPU, 4GB RAM, HA, 50GB) | F24: 178.48 | G24: =F24*0.709
A25: ذاكرة التخزين المؤقت (Redis) | B25: ElastiCache cache.t4g.small (Multi-AZ) | C25: 49.64 | D25: =C25*0.709 | E25: Memorystore Redis Standard (HA, 1.37GB RAM) | F25: 98.01 | G25: =F25*0.709
A26: موزع الأحمال (Load Balancer) | B26: 1 ALB (2 LCU avg) | C26: 28.11 | D26: =C26*0.709 | E26: Cloud Load Balancing | F26: 28.25 | G26: =F26*0.709
A27: بوابة العناوين (NAT Gateway) | B27: 2 NAT Gateways (Multi-AZ) | C27: 65.7 | D27: =C27*0.709 | E27: Cloud NAT Gateway | F27: 10 | G27: =F27*0.709
A28: تخزين الملفات (S3 / Storage) | B28: Amazon S3 (200 GB storage & transfer) | C28: 14.6 | D28: =C28*0.709 | E28: Cloud Storage (200 GB storage & transfer) | F28: 14 | G28: =F28*0.709
A29: شبكة توصيل المحتوى (CDN) | B29: CloudFront (500 GB transfer) | C29: 15 | D29: =C29*0.709 | E29: Cloud CDN (500 GB transfer) | F29: 15 | G29: =F29*0.709
A30: تكاليف متنوعة (DNS/Monitoring) | B30: Route 53, CloudWatch, KMS | C30: 15 | D30: =C30*0.709 | E30: Cloud DNS, Cloud KMS, Logs | F30: 15 | G30: =F30*0.709
A31: إجمالي تكاليف البنية التحتية | C31: =SUM(C20:C30) | D31: =SUM(D20:D30) | F31: =SUM(F20:F30) | G31: =SUM(G20:G30)
A34: المستوى الثالث: مرحلة التوسع والمؤسسات (حتى 50,000 مستخدم نشط MAUs)
A35: واجهة المستخدم (Next.js) | B35: 4 Fargate Tasks (1 vCPU, 2 GB RAM) | C35: 144.16 | D35: =C35*0.709 | E35: 4 Cloud Run Instances (1 vCPU, 2 GB RAM) | F35: 235.47 | G35: =F35*0.709
A36: الخلفية (Django Backend) | B36: 4 Fargate Tasks (2 vCPU, 4 GB RAM) | C36: 288.32 | D36: =C36*0.709 | E36: 4 Cloud Run Instances (2 vCPU, 4 GB RAM) | F36: 470.94 | G36: =F36*0.709
A37: المهام الخلفية (Celery Worker) | B37: 4 Fargate Tasks (1 vCPU, 2 GB RAM) | C37: 144.16 | D37: =C37*0.709 | E37: 4 Cloud Run Instances (1 vCPU, 2 GB RAM) | F37: 235.47 | G37: =F37*0.709
A38: مجدول المهام (Celery Beat) | B38: 1 Fargate Task (0.5 vCPU, 1.0 GB RAM) | C38: 18.02 | D38: =C38*0.709 | E38: 1 Cloud Run Instance (0.5 vCPU, 1.0 GB RAM) | F38: 29.43 | G38: =F38*0.709
A39: قاعدة البيانات (PostgreSQL) | B39: RDS db.m6g.large (Multi-AZ, 200GB SSD) | C39: 333.62 | D39: =C39*0.709 | E39: Cloud SQL Custom (2 vCPU, 8GB RAM, HA, 200GB) | F39: 270.36 | G39: =F39*0.709
A40: ذاكرة التخزين المؤقت (Redis) | B40: ElastiCache cache.m6g.large (Multi-AZ) | C40: 227.76 | D40: =C40*0.709 | E40: Memorystore Redis Standard (HA, 6.38GB RAM) | F40: 456.43 | G40: =F40*0.709
A41: موزع الأحمال (Load Balancer) | B41: 1 ALB (10 LCU avg) | C41: 74.83 | D41: =C41*0.709 | E41: Cloud Load Balancing | F41: 68.25 | G41: =F41*0.709
A42: بوابة العناوين (NAT Gateway) | B42: 2 NAT Gateways (Multi-AZ) | C42: 65.7 | D42: =C42*0.709 | E42: Cloud NAT Gateway | F42: 15 | G42: =F42*0.709
A43: تخزين الملفات (S3 / Storage) | B43: Amazon S3 (1 TB storage & transfer) | C43: 73 | D43: =C43*0.709 | E43: Cloud Storage (1 TB storage & transfer) | F43: 70 | G43: =F43*0.709
A44: شبكة توصيل المحتوى (CDN) | B44: CloudFront (2 TB transfer) | C44: 50 | D44: =C44*0.709 | E44: Cloud CDN (2 TB transfer) | F44: 50 | G44: =F44*0.709
A45: تكاليف متنوعة (DNS/WAF) | B45: Route 53, CloudWatch, WAF | C45: 50 | D45: =C45*0.709 | E45: Cloud Armor (WAF), DNS, Logs | F45: 50 | G45: =F45*0.709
...

Sheet التكاليف التشغيلية الإجمالية
A1: إجمالي التكاليف التشغيلية الشهرية (بدون SMS وبدون صيانة مع إضافة الاحتياطي)
A3: مستوى النمو (MAUs) | B3: البنية التحتية AWS (JOD) | C3: البنية التحتية GCP (JOD) | D3: اسم النطاق (JOD) | E3: البريد الإلكتروني (JOD) | F3: نسخ احتياطي وأمان (JOD) | G3: إجمالي مصاريف AWS (JOD) | H3: إجمالي مصاريف GCP (JOD) | I3: الفارق المالي لصالح AWS (JOD)
A4: المستوى الأول (1k MAUs) | B4: ='البنية التحتية (AWS vs GCP)'!D16 | C4: ='البنية التحتية (AWS vs GCP)'!G16 | D4: 1 | E4: 0.35 | F4: 5 | G4: =B4+D4+E4+F4 | H4: =C4+D4+E4+F4 | I4: =H4-G4
A5: المستوى الثاني (10k MAUs) | B5: ='البنية التحتية (AWS vs GCP)'!D30 | C5: ='البنية التحتية (AWS vs GCP)'!G30 | D5: 1 | E5: 3.55 | F5: 15 | G5: =B5+D5+E5+F5 | H5: =C5+D5+E5+F5 | I5: =H5-G5
A6: المستوى الثالث (50k MAUs) | B6: ='البنية التحتية (AWS vs GCP)'!D44 | C6: ='البنية التحتية (AWS vs GCP)'!G44 | D6: 1 | E6: 17.73 | F6: 50 | G6: =B6+D6+E6+F6 | H6: =C6+D6+E6+F6 | I6: =H6-G6

Sheet تسعير باقات الحد الأدنى
A1: جدول باقات الحد الأدنى للتسعير ومحاكاة الأرباح الصافية
A3: 1. هيكل تسعير باقات الحد الأدنى ومحدداتها
A5: اسم الباقة | B5: السعر شهرياً (JOD) | C5: السعر سنوياً (JOD) | D5: عمولة الإحالة | E5: قيمة العمولة شهرياً (JOD) | F5: صافي إيراد المنصة/مشترك | G5: الحد الأقصى للطلاب | H5: الحد الأقصى للموظفين | I5: الحد الأقصى للفروع
A6: باقة البداية (Basic Plan) | B6: 15 | C6: 153 | D6: 0.1 | E6: =B6*D6 | F6: =B6-E6 | G6: 150 | H6: 5 | I6: 1
A7: باقة النمو (Growth Plan) | B7: 25 | C7: 255 | D7: 0.12 | E7: =B7*D7 | F7: =B7-E7 | G7: 600 | H7: 15 | I7: 3
A8: باقة الاحتراف (Enterprise) | B8: 45 | C8: 459 | D8: 0.15 | E8: =B8*D8 | F8: =B8-E8 | G8: 2000 | H8: غير محدود | I8: غير محدود
A10: 2. محاكاة الأرباح الشهرية ونقاط التعادل لباقات الحد الأدنى
A12: باقة محاكاة المستوى | B12: عدد المشتركين المفترض | C12: إجمالي الإيرادات شهرياً (JOD) | D12: عمولات الإحالة شهرياً (JOD) | E12: مصاريف تشغيل المنصة (JOD) | F12: صافي الأرباح شهرياً (JOD) | G12: هامش الربح الصافي (%) | H12: المشتركون لنقطة التعادل | I12: ملاحظة
A13: المستوى الأول (باقة البداية) | B13: 15 | C13: =B13*'تسعير باقات الحد الأدنى'!B6 | D13: =B13*'تسعير باقات الحد الأدنى'!E6 | E13: ='التكاليف التشغيلية الإجمالية'!G4 | F13: =C13-D13-E13 | G13: =F13/C13 | H13: =E13/'تسعير باقات الحد الأدنى'!F6 | I13: تغطية للمصاريف مع هامش جيد
A14: المستوى الثاني (باقة النمو) | B14: 50 | C14: =B14*'تسعير باقات الحد الأدنى'!B7 | D14: =B14*'تسعير باقات الحد الأدنى'!E7 | E14: ='التكاليف التشغيلية الإجمالية'!G5 | F14: =C14-D14-E14 | G14: =F14/C14 | H14: =E14/'تسعير باقات الحد الأدنى'!F7 | I14: زيادة سريعة في الربحية
A15: المستوى الثالث (الباقة الاحترافية) | B15: 150 | C15: =B15*'تسعير باقات الحد الأدنى'!B8 | D15: =B15*'تسعير باقات الحد الأدنى'!E8 | E15: ='التكاليف التشغيلية الإجمالية'!G6 | F15: =C15-D15-E15 | G15: =F15/C15 | H15: =E15/'تسعير باقات الحد الأدنى'!F8 | I15: هامش ربح مرتفع وتوسع كبير

Sheet تسعير الخبراء والسوق الأردني
A1: جدول باقات التسعير المقترح من خبراء السوق الأردني
A3: 1. هيكل تسعير الخبراء (توازن القيمة والانتشار بالأردن)
A5: اسم الباقة | B5: السعر شهرياً (JOD) | C5: السعر سنوياً (JOD) | D5: عمولة الإحالة | E5: قيمة العمولة شهرياً (JOD) | F5: صافي إيراد المنصة/مشترك | G5: الحد الأقصى للطلاب | H5: الحد الأقصى للموظفين | I5: الحد الأقصى للفروع
A6: باقة البداية (Basic Plan) | B6: 29 | C6: 296 | D6: 0.1 | E6: =B6*D6 | F6: =B6-E6 | G6: 150 | H6: 5 | I6: 1
A7: باقة النمو (Growth Plan) | B7: 59 | C7: 602 | D7: 0.12 | E7: =B7*D7 | F7: =B7-E7 | G7: 600 | H7: 15 | I7: 3
A8: باقة الاحتراف (Enterprise) | B8: 119 | C8: 1214 | D8: 0.15 | E8: =B8*D8 | F8: =B8-E8 | G8: 2000 | H8: غير محدود | I8: غير محدود
A10: 2. محاكاة الأرباح الشهرية ونقاط التعادل لتسعير الخبراء
A12: باقة محاكاة المستوى | B12: عدد المشتركين المفترض | C12: إجمالي الإيرادات شهرياً (JOD) | D12: عمولات الإحالة شهرياً (JOD) | E12: مصاريف تشغيل المنصة (JOD) | F12: صافي الأرباح شهرياً (JOD) | G12: هامش الربح الصافي (%) | H12: المشتركون لنقطة التعادل | I12: ملاحظة
A13: المستوى الأول (باقة البداية) | B13: 15 | C13: =B13*'تسعير الخبراء والسوق الأردني'!B6 | D13: =B13*'تسعير الخبراء والسوق الأردني'!E6 | E13: ='التكاليف التشغيلية الإجمالية'!G4 | F13: =C13-D13-E13 | G13: =F13/C13 | H13: =E13/'تسعير الخبراء والسوق الأردني'!F6 | I13: أرباح ممتازة ونسبة انتشار واسعة
A14: المستوى الثاني (باقة النمو) | B14: 50 | C14: =B14*'تسعير الخبراء والسوق الأردني'!B7 | D14: =B14*'تسعير الخبراء والسوق الأردني'!E7 | E14: ='التكاليف التشغيلية الإجمالية'!G5 | F14: =C14-D14-E14 | G14: =F14/C14 | H14: =E14/'تسعير الخبراء والسوق الأردني'!F7 | I14: إيرادات وصافي ربح مرتفع جداً
A15: المستوى الثالث (الباقة الاحترافية) | B15: 150 | C15: =B15*'تسعير الخبراء والسوق الأردني'!B8 | D15: =B15*'تسعير الخبراء والسوق الأردني'!E8 | E15: ='التكاليف التشغيلية الإجمالية'!G6 | F15: =C15-D15-E15 | G15: =F15/C15 | H15: =E15/'تسعير الخبراء والسوق الأردني'!F8 | I15: أرباح هائلة وتوسع استثماري ناجح

Sheet محاكاة نمو 12 شهر (AWS)
A1: توقعات ومحاكاة التدفقات النقدية والأرباح للسنة الأولى (12 شهراً)
A3: الشهر | B3: عدد الأندية المشتركة | C3: إجمالي الإيرادات (JOD) | D3: رسوم بوابة الدفع 3% (JOD) | E3: عمولات نظام الإحالة (JOD) | F3: مصاريف تشغيل السيرفر (JOD) | G3: صافي الربح الشهري (JOD) | H3: التدفق النقدي المتراكم (JOD)
A4: الشهر 1 | B4: 3 | C4: 145.5 | D4: 4.37 | E4: 17.58 | F4: 72.24 | G4: =C4-D4-E4-F4 | H4: =G4
A5: الشهر 2 | B5: 5 | C5: 242.5 | D5: 7.28 | E5: 29.3 | F5: 72.24 | G5: =C5-D5-E5-F5 | H5: =H4+G5
A6: الشهر 3 | B6: 8 | C6: 388 | D6: 11.64 | E6: 46.88 | F6: 72.24 | G6: =C6-D6-E6-F6 | H6: =H5+G6
A7: الشهر 4 | B7: 12 | C7: 582 | D7: 17.46 | E7: 70.32 | F7: 72.24 | G7: =C7-D7-E7-F7 | H7: =H6+G7
A8: الشهر 5 | B8: 18 | C8: 873 | D8: 26.19 | E8: 105.48 | F8: 72.24 | G8: =C8-D8-E8-F8 | H8: =H7+G8
A9: الشهر 6 | B9: 25 | C9: 1212.5 | D9: 36.38 | E9: 146.5 | F9: 344.56 | G9: =C9-D9-E9-F9 | H9: =H8+G9
A10: الشهر 7 | B10: 35 | C10: 1697.5 | D10: 50.93 | E10: 205.1 | F10: 344.56 | G10: =C10-D10-E10-F10 | H10: =H9+G10
A11: الشهر 8 | B11: 48 | C11: 2328 | D11: 69.84 | E11: 281.28 | F11: 344.56 | G11: =C11-D11-E11-F11 | H11: =H10+G11
A12: الشهر 9 | B12: 62 | C12: 3007 | D12: 90.21 | E12: 363.32 | F12: 344.56 | G12: =C12-D12-E12-F12 | H12: =H11+G12
A13: الشهر 10 | B13: 78 | C13: 3783 | D13: 113.49 | E13: 457.08 | F13: 344.56 | G13: =C13-D13-E13-F13 | H13: =H12+G13
A14: الشهر 11 | B14: 95 | C14: 4607.5 | D14: 138.23 | E14: 556.7 | F14: 344.56 | G14: =C14-D14-E14-F14 | H14: =H13+G14
A15: الشهر 12 | B15: 115 | C15: 5577.5 | D15: 167.33 | E15: 673.9 | F15: 344.56 | G15: =C15-D15-E15-F15 | H15: =H14+G15
A16: المجموع السنوي | C16: =SUM(C4:C15) | D16: =SUM(D4:D15) | E16: =SUM(E4:E15) | F16: =SUM(F4:F15) | G16: =SUM(G4:G15)

Sheet المقاييس المالية (LTV & CAC)
A1: تحليل مقاييس قيمة العميل مدى الحياة وتكلفة الاستحواذ (LTV / CAC)
A3: 1. مقارنة المقاييس بين تسعير الحد الأدنى وتسعير الخبراء بالسوق الأردني
A5: الباقة ونموذج التسعير | B5: متوسط بقاء النادي (شهر) | C5: قيمة العميل مدى الحياة LTV (JOD) | D5: تكلفة الاستحواذ CAC (عمولات الإحالة JOD) | E5: نسبة LTV : CAC (الذهبية > 3) | F5: رسوم بوابة الدفع لكل حركة JOD | G5: جدوى الاستثمار بالعميل
A6: البداية - تسعير الحد الأدنى (15 JOD) | B6: 18 | C6: =B6*15.0 | D6: =B6*1.5 | E6: =C6/D6 | F6: 0.70 JOD | G6: مستقر ومناسب للانتشار
A7: البداية - تسعير الخبراء (29 JOD) | B7: 18 | C7: =B7*29.0 | D7: =B7*2.9 | E7: =C7/D7 | F7: 1.12 JOD | G7: ممتاز جداً لتمويل الإحالات
A8: النمو - تسعير الحد الأدنى (25 JOD) | B8: 24 | C8: =B8*25.0 | D8: =B8*3.0 | E8: =C8/D8 | F8: 1.00 JOD | G8: هامش ربح جيد جداً
A9: النمو - تسعير الخبراء (59 JOD) | B9: 24 | C9: =B9*59.0 | D9: =B9*7.08 | E9: =C9/D9 | F9: 2.02 JOD | G9: أعلى كفاءة استثمارية للمنصة
A10: الاحتراف - تسعير الحد الأدنى (45 JOD) | B10: 36 | C10: =B10*45.0 | D10: =B10*6.75 | E10: =C10/D10 | F10: 1.60 JOD | G10: آمن ومغري جداً للأندية
A11: الاحتراف - تسعير الخبراء (119 JOD) | B11: 36 | C11: =B11*119.0 | D11: =B11*17.85 | E11: =C11/D11 | F11: 3.82 JOD | G11: أرباح قياسية بمقاييس ممتازة
A13: ملاحظة: تظهر نسبة LTV : CAC تفوقاً هائلاً ونمواً صحياً للمنصة، حيث تتجاوز النسبة الذهبية (3.0) بشكل دائم، مما يثبت نجاح وجدوى الاستثمار المالي بالمنصة.
